Workbook

Sheet Hoja1
A1: Semana | B1: Semana | C1: Fecha | D1: Día | E1: Tipo | F1: Km | G1: Tiempo | H1: Ritmo total | I1: Repeticiones | J1: Trabajo tiempo | K1: Trabajo distancia | L1: Ritmo (min/km)
A2: 22 | B2: 55
A3: 21 | B3: 65
A4: 20 | B4: 73
A5: 19 | B5: =SUM(F5:F11) -> 67.25 | C5: 45264 | D5: Lunes | F5: 8.25 | G5: 39
C6: 45265 | D6: Martes | E6: Velocidad en media distancia | F6: 12 | G6: 52
C7: 45266 | D7: Miércoles | F7: Descanso
C8: 45267 | D8: Jueves | E8: Intervalos progresivos | F8: 15 | H8: =G8/F8 -> 0 | I8: 8 | K8: 250 | L8: 0.13888889
C9: 45268 | D9: Viernes | E9: Intervalos largos | F9: Descanso
C10: 45269 | D10: Sábado | E10: Mitad rápida / Mitad lento | F10: 20 | G10: 92 | H10: =G10/F10 -> 4.6
C11: 45270 | D11: Domingo | E11: Rec activa | F11: 12 | G11: 60 | H11: =G11/F11 -> 5
A12: 18 | B12: =SUM(F12:F18) -> 44.74 | C12: 45271 | D12: Lunes | E12: A buen ritmo (playa) | F12: 10.5 | G12: 48 | H12: =G12/F12 -> 4.5714286
C13: 45272 | D13: Martes | E13: Intervalos progresivos | F13: 21.24 | G13: 105 | H13: =G13/F13 -> 4.9435028
C14: 45273 | D14: Miércoles | E14: Descanso
C15: 45274 | D15: Jueves | E15: Descanso
C16: 45275 | D16: Viernes | E16: Descanso
C17: 45276 | D17: Sábado | E17: Descanso
C18: 45277 | D18: Domingo | E18: Intervalos largos rápidos | F18: 13 | G18: 60 | H18: =G18/F18 -> 4.6153846
A19: 17 | B19: =SUM(F19:F25) -> 51.83 | C19: 45278 | D19: Lunes | E19: Descanso
C20: 45279 | D20: Martes | E20: Descanso
C21: 45280 | D21: Miércoles | E21: Rec activa | F21: 8 | G21: 36 | H21: =G21/F21 -> 4.5
C22: 45281 | D22: Jueves | E22: Rec activa lerdo | F22: 9.5 | G22: 49 | H22: =G22/F22 -> 5.1578947
C23: 45282 | D23: Viernes | E23: Subidas y bajadas | F23: 15.23 | G23: 68 | H23: =G23/F23 -> 4.464872
C24: 45283 | D24: Sábado | E24: Velocidad | F24: 8 | G24: 34 | H24: =G24/F24 -> 4.25
C25: 45284 | D25: Domingo | E25: Rec activa | F25: 11.1 | G25: 49 | H25: =G25/F25 -> 4.4144144
A26: 16 | B26: =SUM(F26:F32) -> 70.69 | C26: 45285 | D26: Lunes | E26: Velocidad en distancia | F26: 17 | G26: 75 | H26: =G26/F26 -> 4.4117647
C27: 45286 | D27: Martes | E27: 10K rápido | F27: 10.24 | G27: 40 | H27: =G27/F27 -> 3.90625
C28: 45287 | D28: Miércoles | E28: Descanso
C29: 45288 | D29: Jueves | E29: Velocidad en media distancia | F29: 15 | G29: 65 | H29: =G29/F29 -> 4.3333333
C30: 45289 | D30: Viernes | E30: Descanso
C31: 45290 | D31: Sábado | E31: Media a ritmo fondo | F31: 21.2 | G31: 97 | H31: =G31/F31 -> 4.5754717
C32: 45291 | D32: Domingo | E32: Rec activa lerdo | F32: 7.25 | G32: 38 | H32: =G32/F32 -> 5.2413793
A33: 15 | B33: =SUM(F33:F39) -> 30.6 | C33: 45292 | D33: Lunes | E33: Descanso
C34: 45293 | D34: Martes | E34: Velocidad en media distancia | F34: 15 | G34: 64 | H34: =G34/F34 -> 4.2666667
C35: 45294 | D35: Miércoles | E35: Rec activa | F35: 5.6 | G35: 25 | H35: =G35/F35 -> 4.4642857
C36: 45295 | D36: Jueves | E36: Descanso
C37: 45296 | D37: Viernes | E37: Descanso
C38: 45297 | D38: Sábado | E38: 10K rápido | F38: 10 | G38: 36 | H38: =G38/F38 -> 3.6
C39: 45298 | D39: Domingo | E39: Descanso
A40: 14 | B40: =SUM(F40:F46) -> 14.6 | C40: 45299 | D40: Lunes | E40: Descanso
...

Sheet Data
A1: Datos | B1: Tiempo reloj | C1: Minutos | D1: Distancia (m) | E1: km
A2: Tiempo en 10k | B2: 0.024305556 | C2: =HOUR(B2)*60+MINUTE(B2)+SECOND(B2)/60 -> 35
A3: Pasadas de 200m | B3: 0.0022569444 | C3: =HOUR(B3)*60+MINUTE(B3)+SECOND(B3)/60 -> 3.25
A4: Ritmo fondo | B4: 0.0032986111 | C4: =HOUR(B4)*60+MINUTE(B4)+SECOND(B4)/60 -> 4.75
A5: Ritmo cómodo | B5: 0.0031828704 | C5: =HOUR(B5)*60+MINUTE(B5)+SECOND(B5)/60 -> 4.5833333
A6: Ritmo promedio | B6: =B5*0.95 -> 0.0030237269 | C6: =HOUR(B6)*60+MINUTE(B6)+SECOND(B6)/60 -> 4.35
A7: Máxima distancia corrida | B7: 0.12083333 | C7: =HOUR(B7)*60+MINUTE(B7)+SECOND(B7)/60 -> 174 | D7: 42000
A8: Distancia máxima diaria | D8: 25000
A9: Distancia promedio diaria | D9: 10000
A10: Distancia promedio semanal | D10: 70000 | E10: =D10/1000 -> 70
A11: Edad | B11: 30
A12: Sexo | B12: 0 | C12: Es Hombre?
A13: Peso | B13: 70
A14: Altura | B14: 1.78 | C14: Bajo | D14: Normal | E14: Sobrepeso | F14: Obeso
A15: Años corriendo | B15: 4
A16: Porcentaje mejora pSE | B16: {=INDEX(ProbA!B2:C11, B15, 1)} -> 6
A17: Porcentaje mejora Elite | B17: {=INDEX(ProbA!B2:C11, B15, 2)} -> 2
A19: Km Semanales pSE | B19: {=INDEX(KmSemanales!B2:E52, (B11-19), (IF(B12=1,1,3)))} -> 60
A20: Km Semanales Elite | B20: {=INDEX(KmSemanales!B2:E52, (B11-19), (IF(B12=1,2,4)))} -> 120
A21: IMC | B21: =B13/(B14*B14) -> 22.09317 | C21: Menor a 18,5 | D21: Entre 18,5 y 24,9 | E21: Entre 25 y 29,9 | F21: Mayor a 30
A22: IMC ideal | B22: 20 | C22: Entre 19 y 20,5 (elite) y entre 20 y 22 (Sub 3h) | D22: Promedio maratón NY 23.3
A24: RItmo estimado máximo
A25: Carrera más rápida (metros) | B25: 10000
A26: Tiempo (en minutos) | B26: 36
A27: VO2max (Jack Daniels) | B27: =(0.2*(B25/B26))+3.5 -> 59.055556 | C27: ml/kg/min
A28: FC MAX | B28: 182 | C28: =IF(B12=1, 208-(0.7*B11), IF(B12=0, 206-(0.88*B11), "Error")) -> 179.6 | D28: (Estimado)
A29: FC MIN (reposo) | B29: 44
A30: VO2max (combinado) | B30: =(B27*0.6)+((15.3*(B28/B29))*0.4) -> 60.747879
A31: VO2max (prommaxsexed) | B31: {=INDEX(VO2MAX!B2:C52,(B11-19),(IF(B12=1,1,2)))} -> 47.6
A32: VO2max (prommaxElite) | B32: {=INDEX(VO2MAXElite!B2:C52,(B11-19),(IF(B12=1,1,2)))} -> 58
A34: Entrenamiento velocidad pasadas cortas (100-200m)
A35: Pasadas | B35: =ROUNDDOWN(D9/1000,1) -> 10
A36: Ritmo | B36: =B3*0.975 -> 0.0022005208
A37: Descanso intermedio | B37: 1 minuto
A38: Ritmo descanso | B38: =B4*1.05 -> 0.0034635417
A39: Siempre arranca con 2-4 km suaves en leve progresivo y se termina con ritmo suave (mínimo 2km)
A40: Objetivo: Mantener tiempo en pasadas de 200m disminuyendo 0.5-1segundo entre pasadas
A42: Entrenamiento tempo (en orden de ejecución)
A43: 3-4km calentamiento suave
A44: Intervalo 1 kms: | B44: =ROUNDDOWN(D8/5000,0) -> 5
...

Sheet Resultados
A1: Resultados para ejecución de informe | B1: Column1 | C1: (Negativo implica mejora frente a promedio)
A3: Posibilidad de mejora IMC pSE (kg/m2) | B3: =Data!B21-Data!B22 -> 2.0931701 | C3: X
A4: Posibilidad de mejora IMC Elite (kg/m2) | B4: =Data!B21-Data!B22+1.5 -> 3.5931701 | C4: X
A5: Posibilidad de mejora en VO2MAX pSE (ml/kg/min) | B5: =Data!B31-Data!B30 -> -13.147879 | C5: X
A6: Posibilidad de mejora en VO2MAX Elite (ml/kg/min) | B6: =Data!B32-Data!B30 -> -2.7478788 | C6: X
A7: Posibilidad de mejora en FCmax pSE (ppm) | B7: =Data!C28-Data!B28 -> -2.4 | C7: X
A8: Posibilidad de mejora años entrenamiento pSE (%) | B8: =Data!B16 -> 6
A9: Posibilidad de mejora años entrenamiento Elite (%) | B9: =Data!B17 -> 2
A10: Posibilidad de mejora en Km Semanales sPE (km) | B10: =Data!B19-Data!D10/1000 -> -10 | C10: X
A11: Posibilidad de mejora en Km Semanales Elite (km) | B11: =Data!B20-Data!D10/1000 -> 50 | C11: X

Sheet VO2MAXElite
A1: Edad | B1: Hombres (ml/kg/min) | C1: Mujeres (ml/kg/min)
A2: 20 | B2: 70 | C2: 60
A3: 21 | B3: 69.8 | C3: 59.8
A4: 22 | B4: 69.6 | C4: 59.6
A5: 23 | B5: 69.4 | C5: 59.4
A6: 24 | B6: 69.2 | C6: 59.2
A7: 25 | B7: 69 | C7: 59
A8: 26 | B8: 68.8 | C8: 58.8
A9: 27 | B9: 68.6 | C9: 58.6
A10: 28 | B10: 68.4 | C10: 58.4
A11: 29 | B11: 68.2 | C11: 58.2
A12: 30 | B12: 68 | C12: 58
A13: 31 | B13: 67.8 | C13: 57.8
... A52: 70 | B52: 60 | C52: 50

Sheet VO2MAX
A1: Edad | B1: Hombre | C1: Mujer
A2: 20 | B2: 55.4 | C2: 49.6
A3: 21 | B3: 55.2 | C3: 49.4
A4: 22 | B4: 55 | C4: 49.2
A5: 23 | B5: 54.8 | C5: 49
A6: 24 | B6: 54.6 | C6: 48.8
A7: 25 | B7: 54.4 | C7: 48.6
A8: 26 | B8: 54.2 | C8: 48.4
A9: 27 | B9: 54 | C9: 48.2
A10: 28 | B10: 53.8 | C10: 48
A11: 29 | B11: 53.6 | C11: 47.8
A12: 30 | B12: 53.4 | C12: 47.6
A13: 31 | B13: 53.2 | C13: 47.4
... A52: 70 | B52: 45.4 | C52: 39.6

Sheet ProbA
A1: Año | B1: Amateur (%) | C1: Élite (%)
A2: 0 | B2: 0 | C2: 0
A3: 1 | B3: 12 | C3: 5
A4: 2 | B4: 8 | C4: 3
A5: 3 | B5: 6 | C5: 2
A6: 4 | B6: 4 | C6: 1.5
A7: 5 | B7: 3 | C7: 1
A8: 6 | B8: 2.5 | C8: 0.8
A9: 7 | B9: 2 | C9: 0.6
A10: 8 | B10: 1.5 | C10: 0.5
A11: 9 | B11: 1.2 | C11: 0.4
A12: 10 | B12: 1 | C12: 0.3

Sheet KmSemanales
A1: Edad | B1: Hombres (km/semana) | C1: Hombres Élite (km/semana) | D1: Mujeres (km/semana) | E1: Mujeres Élite (km/semana)
A2: 20 | B2: 50 | C2: 120 | D2: 40 | E2: 100
A3: 21 | B3: 52 | C3: 122 | D3: 42 | E3: 102
A4: 22 | B4: 54 | C4: 124 | D4: 44 | E4: 104
A5: 23 | B5: 56 | C5: 126 | D5: 46 | E5: 106
A6: 24 | B6: 58 | C6: 128 | D6: 48 | E6: 108
A7: 25 | B7: 60 | C7: 130 | D7: 50 | E7: 110
A8: 26 | B8: 62 | C8: 132 | D8: 52 | E8: 112
A9: 27 | B9: 64 | C9: 134 | D9: 54 | E9: 114
A10: 28 | B10: 66 | C10: 136 | D10: 56 | E10: 116
A11: 29 | B11: 68 | C11: 138 | D11: 58 | E11: 118
A12: 30 | B12: 70 | C12: 140 | D12: 60 | E12: 120
A13: 31 | B13: 72 | C13: 142 | D13: 62 | E13: 122
... A52: 70 | B52: 10 | C52: 80 | D52: 1 | E52: 60
